<?xml version="1.0" ?>
<!-- =================================================================================== -->
<!-- |    This document was autogenerated by xacro from src/sme_robot_mobile_description/urdf/sme_robot_mobile_robot.xacro | -->
<!-- |    EDITING THIS FILE BY HAND IS NOT RECOMMENDED                                 | -->
<!-- =================================================================================== -->
<robot name="robot">
  <!-- 
    INSTANTIATE ROBOT
    1. Create the mobile base (chassis + wheels)
    2. Attach sensors to the chassis
  -->
  <!-- 
      BASE FOOTPRINT
      This is a virtual link that sits on the ground (z=0). 
      It's useful for navigation algorithms to know where the "floor" is relative to the robot.
    -->
  <link name="robot_footprint"/>
  <joint name="robot_footprint_joint" type="fixed">
    <parent link="robot_footprint"/>
    <child link="robot_chassis"/>
    <origin rpy="0 0 0" xyz="0 0 0.08"/>
    <!-- Raise chassis 8cm off ground (wheel diameter) -->
  </joint>
  <!-- 
      CHASSIS LINK (Virtual - for collision and inertia)
      The main body of the robot.
    -->
  <link name="robot_chassis">
    <visual>
      <geometry>
        <box size="0.26 0.245 0.12"/>
      </geometry>
      <material name="black">
        <color rgba="0.1 0.1 0.1 1"/>
      </material>
    </visual>
    <collision>
      <geometry>
        <box size="0.26 0.245 0.12"/>
      </geometry>
    </collision>
    <inertial>
      <mass value="15.0"/>
      <!-- Heavy base for stability -->
      <inertia ixx="0.1" ixy="0" ixz="0" iyy="0.1" iyz="0" izz="0.1"/>
    </inertial>
  </link>
  <gazebo reference="robot_chassis">
    <visual>
      <material>
        <ambient>0.2 0.2 0.2 1</ambient>
        <diffuse>0.2 0.2 0.2 1</diffuse>
        <specular>0.2 0.2 0.2 1</specular>
      </material>
    </visual>
  </gazebo>
  <!-- 
      BOTTOM PLATE
      Lower acrylic plate (3mm thickness)
    -->
  <link name="robot_base_link">
    <visual>
      <geometry>
        <box size="0.26 0.245 0.003"/>
        <!-- 26cm x 24.5cm x 3mm -->
      </geometry>
      <material name="black">
        <color rgba="0.1 0.1 0.1 1"/>
      </material>
    </visual>
  </link>
  <gazebo reference="robot_base_link">
    <visual>
      <material>
        <ambient>0.1 0.1 0.1 1</ambient>
        <diffuse>0.1 0.1 0.1 1</diffuse>
        <specular>0.1 0.1 0.1 1</specular>
      </material>
    </visual>
  </gazebo>
  <joint name="robot_base_link_joint" type="fixed">
    <parent link="robot_chassis"/>
    <child link="robot_base_link"/>
    <origin rpy="0 0 0" xyz="0 0 0"/>
    <!-- Bottom of chassis (12cm/2 = 6cm down) -->
  </joint>
  <!-- 
      TOP PLATE
      Upper acrylic plate (3mm thickness)
    -->
  <link name="robot_top_plate">
    <visual>
      <geometry>
        <box size="0.26 0.245 0.003"/>
        <!-- 26cm x 24.5cm x 3mm -->
      </geometry>
      <material name="black">
        <color rgba="0.1 0.1 0.1 1"/>
      </material>
    </visual>
  </link>
  <gazebo reference="robot_top_plate">
    <visual>
      <material>
        <ambient>0.1 0.1 0.1 1</ambient>
        <diffuse>0.1 0.1 0.1 1</diffuse>
        <specular>0.1 0.1 0.1 1</specular>
      </material>
    </visual>
  </gazebo>
  <joint name="robot_top_plate_joint" type="fixed">
    <parent link="robot_base_link"/>
    <child link="robot_top_plate"/>
    <origin rpy="0 0 0" xyz="0 0 0.04"/>
    <!-- Top of chassis (12cm/2 = 6cm up) -->
  </joint>
  <link name="robot_front_left_wheel">
    <visual>
      <geometry>
        <cylinder length="0.037" radius="0.04"/>
        <!-- 80mm diameter, 37mm width -->
      </geometry>
      <material name="black">
        <color rgba="0 0 0 1"/>
      </material>
    </visual>
    <collision>
      <geometry>
        <cylinder length="0.037" radius="0.04"/>
      </geometry>
    </collision>
    <inertial>
      <mass value="1.0"/>
      <inertia ixx="0.01" ixy="0" ixz="0" iyy="0.01" iyz="0" izz="0.01"/>
    </inertial>
  </link>
  <gazebo reference="robot_front_left_wheel">
    <visual>
      <material>
        <ambient>0.1 0.1 0.1 1</ambient>
        <diffuse>0.1 0.1 0.1 1</diffuse>
        <specular>0.1 0.1 0.1 1</specular>
      </material>
    </visual>
  </gazebo>
  <joint name="robot_front_left_wheel_joint" type="continuous">
    <parent link="robot_chassis"/>
    <child link="robot_front_left_wheel"/>
    <!-- Rotate cylinder to be upright for a wheel -->
    <origin rpy="-1.5707 0 0" xyz="0.09 0.1412 -0.04"/>
    <axis xyz="0 0 1"/>
    <!-- Rotate around the cylinder's Z axis (which is robot's Y) -->
  </joint>
  <link name="robot_front_right_wheel">
    <visual>
      <geometry>
        <cylinder length="0.037" radius="0.04"/>
        <!-- 80mm diameter, 37mm width -->
      </geometry>
      <material name="black">
        <color rgba="0 0 0 1"/>
      </material>
    </visual>
    <collision>
      <geometry>
        <cylinder length="0.037" radius="0.04"/>
      </geometry>
    </collision>
    <inertial>
      <mass value="1.0"/>
      <inertia ixx="0.01" ixy="0" ixz="0" iyy="0.01" iyz="0" izz="0.01"/>
    </inertial>
  </link>
  <gazebo reference="robot_front_right_wheel">
    <visual>
      <material>
        <ambient>0.1 0.1 0.1 1</ambient>
        <diffuse>0.1 0.1 0.1 1</diffuse>
        <specular>0.1 0.1 0.1 1</specular>
      </material>
    </visual>
  </gazebo>
  <joint name="robot_front_right_wheel_joint" type="continuous">
    <parent link="robot_chassis"/>
    <child link="robot_front_right_wheel"/>
    <!-- Rotate cylinder to be upright for a wheel -->
    <origin rpy="-1.5707 0 0" xyz="0.09 -0.1412 -0.04"/>
    <axis xyz="0 0 1"/>
    <!-- Rotate around the cylinder's Z axis (which is robot's Y) -->
  </joint>
  <link name="robot_rear_left_wheel">
    <visual>
      <geometry>
        <cylinder length="0.037" radius="0.04"/>
        <!-- 80mm diameter, 37mm width -->
      </geometry>
      <material name="black">
        <color rgba="0 0 0 1"/>
      </material>
    </visual>
    <collision>
      <geometry>
        <cylinder length="0.037" radius="0.04"/>
      </geometry>
    </collision>
    <inertial>
      <mass value="1.0"/>
      <inertia ixx="0.01" ixy="0" ixz="0" iyy="0.01" iyz="0" izz="0.01"/>
    </inertial>
  </link>
  <gazebo reference="robot_rear_left_wheel">
    <visual>
      <material>
        <ambient>0.1 0.1 0.1 1</ambient>
        <diffuse>0.1 0.1 0.1 1</diffuse>
        <specular>0.1 0.1 0.1 1</specular>
      </material>
    </visual>
  </gazebo>
  <joint name="robot_rear_left_wheel_joint" type="continuous">
    <parent link="robot_chassis"/>
    <child link="robot_rear_left_wheel"/>
    <!-- Rotate cylinder to be upright for a wheel -->
    <origin rpy="-1.5707 0 0" xyz="-0.09 0.1412 -0.04"/>
    <axis xyz="0 0 1"/>
    <!-- Rotate around the cylinder's Z axis (which is robot's Y) -->
  </joint>
  <link name="robot_rear_right_wheel">
    <visual>
      <geometry>
        <cylinder length="0.037" radius="0.04"/>
        <!-- 80mm diameter, 37mm width -->
      </geometry>
      <material name="black">
        <color rgba="0 0 0 1"/>
      </material>
    </visual>
    <collision>
      <geometry>
        <cylinder length="0.037" radius="0.04"/>
      </geometry>
    </collision>
    <inertial>
      <mass value="1.0"/>
      <inertia ixx="0.01" ixy="0" ixz="0" iyy="0.01" iyz="0" izz="0.01"/>
    </inertial>
  </link>
  <gazebo reference="robot_rear_right_wheel">
    <visual>
      <material>
        <ambient>0.1 0.1 0.1 1</ambient>
        <diffuse>0.1 0.1 0.1 1</diffuse>
        <specular>0.1 0.1 0.1 1</specular>
      </material>
    </visual>
  </gazebo>
  <joint name="robot_rear_right_wheel_joint" type="continuous">
    <parent link="robot_chassis"/>
    <child link="robot_rear_right_wheel"/>
    <!-- Rotate cylinder to be upright for a wheel -->
    <origin rpy="-1.5707 0 0" xyz="-0.09 -0.1412 -0.04"/>
    <axis xyz="0 0 1"/>
    <!-- Rotate around the cylinder's Z axis (which is robot's Y) -->
  </joint>
  <!-- robot_base_rear_right -->
  <!-- 
      LIDAR SENSOR
      Used for 2D mapping and navigation (AMCL/Gmapping).
    -->
  <link name="robot_lidar_link">
    <visual>
      <geometry>
        <cylinder length="0.05" radius="0.05"/>
      </geometry>
      <material name="black"/>
    </visual>
  </link>
  <joint name="robot_lidar_joint" type="fixed">
    <parent link="robot_top_plate"/>
    <child link="robot_lidar_link"/>
    <origin rpy="0 0 0" xyz="0 0 0.0265"/>
    <!-- Mounted on top of plate: 1.5mm (half plate) + 25mm (half lidar height) -->
  </joint>
  <gazebo reference="robot_lidar_link">
    <visual>
      <material>
        <ambient>0.1 0.1 0.1 1</ambient>
        <diffuse>0.1 0.1 0.1 1</diffuse>
        <specular>0.1 0.1 0.1 1</specular>
      </material>
    </visual>
  </gazebo>
  <!-- 
      CAMERA SENSOR
      Used for visual perception.
    -->
  <link name="robot_camera_link">
    <visual>
      <geometry>
        <box size="0.02 0.05 0.02"/>
      </geometry>
      <material name="black"/>
    </visual>
  </link>
  <gazebo reference="robot_camera_link">
    <visual>
      <material>
        <ambient>0.1 0.1 0.1 1</ambient>
        <diffuse>0.1 0.1 0.1 1</diffuse>
        <specular>0.1 0.1 0.1 1</specular>
      </material>
    </visual>
  </gazebo>
  <joint name="robot_camera_joint" type="fixed">
    <parent link="robot_top_plate"/>
    <child link="robot_camera_link"/>
    <origin rpy="0 0 0" xyz="0.12 0 0.0115"/>
    <!-- Mounted on top of plate: 1.5mm (half plate) + 10mm (half camera height) -->
  </joint>
  <!-- 
      GAZEBO PLUGIN: LIDAR
      This plugin makes the lidar sensor actually publish laser scan data in Gazebo.
    -->
  <gazebo reference="robot_lidar_link">
    <sensor name="robot_lidar_sensor" type="gpu_lidar">
      <pose>0 0 0 0 0 0</pose>
      <visualize>true</visualize>
      <update_rate>10</update_rate>
      <topic>scan</topic>
      <lidar>
        <scan>
          <horizontal>
            <samples>360</samples>
            <resolution>1</resolution>
            <min_angle>-3.14159</min_angle>
            <max_angle>3.14159</max_angle>
          </horizontal>
        </scan>
        <range>
          <min>0.1</min>
          <max>10.0</max>
          <resolution>0.01</resolution>
        </range>
        <noise>
          <type>gaussian</type>
          <mean>0.0</mean>
          <stddev>0.01</stddev>
        </noise>
      </lidar>
    </sensor>
  </gazebo>
  <!-- 
      IMU SENSOR
      Used for orientation and acceleration measurements.
    -->
  <link name="robot_imu_link">
    <visual>
      <geometry>
        <box size="0.02 0.02 0.01"/>
      </geometry>
      <material name="blue">
        <color rgba="0 0 1 1"/>
      </material>
    </visual>
    <inertial>
      <mass value="0.001"/>
      <origin rpy="0 0 0" xyz="0 0 0"/>
      <inertia ixx="1e-6" ixy="0" ixz="0" iyy="1e-6" iyz="0" izz="1e-6"/>
    </inertial>
  </link>
  <gazebo reference="robot_imu_link">
    <visual>
      <material>
        <ambient>0.0 0.0 1.0 1</ambient>
        <diffuse>0.0 0.0 1.0 1</diffuse>
        <specular>0.1 0.1 0.1 1</specular>
      </material>
    </visual>
  </gazebo>
  <joint name="robot_imu_joint" type="fixed">
    <parent link="robot_top_plate"/>
    <child link="robot_imu_link"/>
    <origin rpy="0 0 0" xyz="0 0 0.0115"/>
    <!-- Mounted on top of plate: 1.5mm (half plate) + 10mm (half IMU height) -->
  </joint>
  <!-- 
      GAZEBO PLUGIN: IMU
      This plugin makes the IMU sensor publish orientation, angular velocity, and linear acceleration.
    -->
  <gazebo reference="robot_imu_link">
    <gravity>true</gravity>
    <sensor name="robot_imu_sensor" type="imu">
      <always_on>true</always_on>
      <update_rate>100</update_rate>
      <visualize>true</visualize>
      <topic>imu</topic>
      <pose>0 0 0 0 0 0</pose>
    </sensor>
  </gazebo>
  <!-- 
    GAZEBO PLUGINS
    These are required for the robot to actually move in simulation.
  -->
  <gazebo>
    <!-- Diff Drive (Skid Steer) -->
    <plugin filename="gz-sim-diff-drive-system" name="gz::sim::systems::DiffDrive">
      <left_joint>robot_front_left_wheel_joint</left_joint>
      <left_joint>robot_rear_left_wheel_joint</left_joint>
      <right_joint>robot_front_right_wheel_joint</right_joint>
      <right_joint>robot_rear_right_wheel_joint</right_joint>
      <wheel_separation>0.2824</wheel_separation>
      <wheel_radius>0.04</wheel_radius>
      <odom_publish_frequency>50</odom_publish_frequency>
      <topic>cmd_vel</topic>
      <odom_topic>odom</odom_topic>
      <tf_topic>tf</tf_topic>
      <frame_id>odom</frame_id>
      <child_frame_id>robot_footprint</child_frame_id>
    </plugin>
    <!-- Joint State Publisher -->
    <plugin filename="gz-sim-joint-state-publisher-system" name="gz::sim::systems::JointStatePublisher">
      <topic>joint_states</topic>
    </plugin>
  </gazebo>
</robot>
